2022-11-02 19:56:34,786 - my_application - ERROR - Some error occurred
Traceback (most recent call last):
  File "C:\web_projects\arbitrage_kw\main.py", line 9, in <module>
    raise ValueError("Some error occurred")
ValueError: Some error occurred
2022-11-02 19:57:05,877 - my_application - ERROR - Some error occurred
Traceback (most recent call last):
  File "C:\web_projects\arbitrage_kw\main.py", line 9, in <module>
    raise ValueError("Some error occurred")
ValueError: Some error occurred
2022-11-02 20:04:02,657 - my_application - ERROR - Message: unknown error: net::ERR_CONNECTION_RESET
  (Session info: headless chrome=106.0.5249.121)
Stacktrace:
Backtrace:
	Ordinal0 [0x00DF1ED3+2236115]
	Ordinal0 [0x00D892F1+1807089]
	Ordinal0 [0x00C966FD+812797]
	Ordinal0 [0x00C92C42+797762]
	Ordinal0 [0x00C89C1D+760861]
	Ordinal0 [0x00C8A9FC+764412]
	Ordinal0 [0x00C89E5F+761439]
	Ordinal0 [0x00C89350+758608]
	Ordinal0 [0x00C892C1+758465]
	Ordinal0 [0x00C88113+753939]
	Ordinal0 [0x00C8861D+755229]
	Ordinal0 [0x00C9800E+819214]
	Ordinal0 [0x00CF60CD+1204429]
	Ordinal0 [0x00CE1A8C+1120908]
	Ordinal0 [0x00CF59E2+1202658]
	Ordinal0 [0x00CE18A6+1120422]
	Ordinal0 [0x00CBA73D+960317]
	Ordinal0 [0x00CBB71F+964383]
	GetHandleVerifier [0x0109E7E2+2743074]
	GetHandleVerifier [0x010908D4+2685972]
	GetHandleVerifier [0x00E82BAA+532202]
	GetHandleVerifier [0x00E81990+527568]
	Ordinal0 [0x00D9080C+1837068]
	Ordinal0 [0x00D94CD8+1854680]
	Ordinal0 [0x00D94DC5+1854917]
	Ordinal0 [0x00D9ED64+1895780]
	BaseThreadInitThunk [0x7694FA29+25]
	RtlGetAppContainerNamedObjectPath [0x77677BBE+286]
	RtlGetAppContainerNamedObjectPath [0x77677B8E+238]
Traceback (most recent call last):
  File "C:\web_projects\arbitrage_kw\main_widget.py", line 111, in run
    self.br.run_script()
  File "C:\web_projects\arbitrage_kw\script_instance.py", line 31, in run_script
    self.driver.get('https://leon.bet/ru/live/soccer')
  File "C:\web_projects\arbitrage_kw\venv\lib\site-packages\selenium\webdriver\remote\webdriver.py", line 441, in get
    self.execute(Command.GET, {'url': url})
  File "C:\web_projects\arbitrage_kw\venv\lib\site-packages\selenium\webdriver\remote\webdriver.py", line 429, in execute
    self.error_handler.check_response(response)
  File "C:\web_projects\arbitrage_kw\venv\lib\site-packages\selenium\webdriver\remote\errorhandler.py", line 243, in check_response
    raise exception_class(message, screen, stacktrace)
selenium.common.exceptions.WebDriverException: Message: unknown error: net::ERR_CONNECTION_RESET
  (Session info: headless chrome=106.0.5249.121)
Stacktrace:
Backtrace:
	Ordinal0 [0x00DF1ED3+2236115]
	Ordinal0 [0x00D892F1+1807089]
	Ordinal0 [0x00C966FD+812797]
	Ordinal0 [0x00C92C42+797762]
	Ordinal0 [0x00C89C1D+760861]
	Ordinal0 [0x00C8A9FC+764412]
	Ordinal0 [0x00C89E5F+761439]
	Ordinal0 [0x00C89350+758608]
	Ordinal0 [0x00C892C1+758465]
	Ordinal0 [0x00C88113+753939]
	Ordinal0 [0x00C8861D+755229]
	Ordinal0 [0x00C9800E+819214]
	Ordinal0 [0x00CF60CD+1204429]
	Ordinal0 [0x00CE1A8C+1120908]
	Ordinal0 [0x00CF59E2+1202658]
	Ordinal0 [0x00CE18A6+1120422]
	Ordinal0 [0x00CBA73D+960317]
	Ordinal0 [0x00CBB71F+964383]
	GetHandleVerifier [0x0109E7E2+2743074]
	GetHandleVerifier [0x010908D4+2685972]
	GetHandleVerifier [0x00E82BAA+532202]
	GetHandleVerifier [0x00E81990+527568]
	Ordinal0 [0x00D9080C+1837068]
	Ordinal0 [0x00D94CD8+1854680]
	Ordinal0 [0x00D94DC5+1854917]
	Ordinal0 [0x00D9ED64+1895780]
	BaseThreadInitThunk [0x7694FA29+25]
	RtlGetAppContainerNamedObjectPath [0x77677BBE+286]
	RtlGetAppContainerNamedObjectPath [0x77677B8E+238]

2022-11-02 20:49:27,366 - my_application - ERROR - ('Connection aborted.', ConnectionResetError(10054, 'Удаленный хост принудительно разорвал существующее подключение', None, 10054, None))
Traceback (most recent call last):
  File "C:\web_projects\arbitrage_kw\venv\lib\site-packages\urllib3\connectionpool.py", line 703, in urlopen
    httplib_response = self._make_request(
  File "C:\web_projects\arbitrage_kw\venv\lib\site-packages\urllib3\connectionpool.py", line 449, in _make_request
    six.raise_from(e, None)
  File "<string>", line 3, in raise_from
  File "C:\web_projects\arbitrage_kw\venv\lib\site-packages\urllib3\connectionpool.py", line 444, in _make_request
    httplib_response = conn.getresponse()
  File "C:\Python310\lib\http\client.py", line 1374, in getresponse
    response.begin()
  File "C:\Python310\lib\http\client.py", line 318, in begin
    version, status, reason = self._read_status()
  File "C:\Python310\lib\http\client.py", line 279, in _read_status
    line = str(self.fp.readline(_MAXLINE + 1), "iso-8859-1")
  File "C:\Python310\lib\socket.py", line 705, in readinto
    return self._sock.recv_into(b)
ConnectionResetError: [WinError 10054] Удаленный хост принудительно разорвал существующее подключение

During handling of the above exception, another exception occurred:

Traceback (most recent call last):
  File "C:\web_projects\arbitrage_kw\main_widget.py", line 122, in run
    self.br.run_script()
  File "C:\web_projects\arbitrage_kw\script_instance.py", line 31, in run_script
    self.driver.get('https://leon.bet/ru/live/soccer')
  File "C:\web_projects\arbitrage_kw\venv\lib\site-packages\selenium\webdriver\remote\webdriver.py", line 441, in get
    self.execute(Command.GET, {'url': url})
  File "C:\web_projects\arbitrage_kw\venv\lib\site-packages\selenium\webdriver\remote\webdriver.py", line 427, in execute
    response = self.command_executor.execute(driver_command, params)
  File "C:\web_projects\arbitrage_kw\venv\lib\site-packages\selenium\webdriver\remote\remote_connection.py", line 344, in execute
    return self._request(command_info[0], url, body=data)
  File "C:\web_projects\arbitrage_kw\venv\lib\site-packages\selenium\webdriver\remote\remote_connection.py", line 366, in _request
    response = self._conn.request(method, url, body=body, headers=headers)
  File "C:\web_projects\arbitrage_kw\venv\lib\site-packages\urllib3\request.py", line 78, in request
    return self.request_encode_body(
  File "C:\web_projects\arbitrage_kw\venv\lib\site-packages\urllib3\request.py", line 170, in request_encode_body
    return self.urlopen(method, url, **extra_kw)
  File "C:\web_projects\arbitrage_kw\venv\lib\site-packages\urllib3\poolmanager.py", line 376, in urlopen
    response = conn.urlopen(method, u.request_uri, **kw)
  File "C:\web_projects\arbitrage_kw\venv\lib\site-packages\urllib3\connectionpool.py", line 787, in urlopen
    retries = retries.increment(
  File "C:\web_projects\arbitrage_kw\venv\lib\site-packages\urllib3\util\retry.py", line 550, in increment
    raise six.reraise(type(error), error, _stacktrace)
  File "C:\web_projects\arbitrage_kw\venv\lib\site-packages\urllib3\packages\six.py", line 769, in reraise
    raise value.with_traceback(tb)
  File "C:\web_projects\arbitrage_kw\venv\lib\site-packages\urllib3\connectionpool.py", line 703, in urlopen
    httplib_response = self._make_request(
  File "C:\web_projects\arbitrage_kw\venv\lib\site-packages\urllib3\connectionpool.py", line 449, in _make_request
    six.raise_from(e, None)
  File "<string>", line 3, in raise_from
  File "C:\web_projects\arbitrage_kw\venv\lib\site-packages\urllib3\connectionpool.py", line 444, in _make_request
    httplib_response = conn.getresponse()
  File "C:\Python310\lib\http\client.py", line 1374, in getresponse
    response.begin()
  File "C:\Python310\lib\http\client.py", line 318, in begin
    version, status, reason = self._read_status()
  File "C:\Python310\lib\http\client.py", line 279, in _read_status
    line = str(self.fp.readline(_MAXLINE + 1), "iso-8859-1")
  File "C:\Python310\lib\socket.py", line 705, in readinto
    return self._sock.recv_into(b)
urllib3.exceptions.ProtocolError: ('Connection aborted.', ConnectionResetError(10054, 'Удаленный хост принудительно разорвал существующее подключение', None, 10054, None))
2022-11-02 20:51:13,115 - my_application - ERROR - ('Connection aborted.', ConnectionResetError(10054, 'Удаленный хост принудительно разорвал существующее подключение', None, 10054, None))
Traceback (most recent call last):
  File "C:\web_projects\arbitrage_kw\venv\lib\site-packages\urllib3\connectionpool.py", line 703, in urlopen
    httplib_response = self._make_request(
  File "C:\web_projects\arbitrage_kw\venv\lib\site-packages\urllib3\connectionpool.py", line 449, in _make_request
    six.raise_from(e, None)
  File "<string>", line 3, in raise_from
  File "C:\web_projects\arbitrage_kw\venv\lib\site-packages\urllib3\connectionpool.py", line 444, in _make_request
    httplib_response = conn.getresponse()
  File "C:\Python310\lib\http\client.py", line 1374, in getresponse
    response.begin()
  File "C:\Python310\lib\http\client.py", line 318, in begin
    version, status, reason = self._read_status()
  File "C:\Python310\lib\http\client.py", line 279, in _read_status
    line = str(self.fp.readline(_MAXLINE + 1), "iso-8859-1")
  File "C:\Python310\lib\socket.py", line 705, in readinto
    return self._sock.recv_into(b)
ConnectionResetError: [WinError 10054] Удаленный хост принудительно разорвал существующее подключение

During handling of the above exception, another exception occurred:

Traceback (most recent call last):
  File "C:\web_projects\arbitrage_kw\main_widget.py", line 122, in run
    self.br.run_script()
  File "C:\web_projects\arbitrage_kw\script_instance.py", line 31, in run_script
    self.driver.get('https://leon.bet/ru/live/soccer')
  File "C:\web_projects\arbitrage_kw\venv\lib\site-packages\selenium\webdriver\remote\webdriver.py", line 441, in get
    self.execute(Command.GET, {'url': url})
  File "C:\web_projects\arbitrage_kw\venv\lib\site-packages\selenium\webdriver\remote\webdriver.py", line 427, in execute
    response = self.command_executor.execute(driver_command, params)
  File "C:\web_projects\arbitrage_kw\venv\lib\site-packages\selenium\webdriver\remote\remote_connection.py", line 344, in execute
    return self._request(command_info[0], url, body=data)
  File "C:\web_projects\arbitrage_kw\venv\lib\site-packages\selenium\webdriver\remote\remote_connection.py", line 366, in _request
    response = self._conn.request(method, url, body=body, headers=headers)
  File "C:\web_projects\arbitrage_kw\venv\lib\site-packages\urllib3\request.py", line 78, in request
    return self.request_encode_body(
  File "C:\web_projects\arbitrage_kw\venv\lib\site-packages\urllib3\request.py", line 170, in request_encode_body
    return self.urlopen(method, url, **extra_kw)
  File "C:\web_projects\arbitrage_kw\venv\lib\site-packages\urllib3\poolmanager.py", line 376, in urlopen
    response = conn.urlopen(method, u.request_uri, **kw)
  File "C:\web_projects\arbitrage_kw\venv\lib\site-packages\urllib3\connectionpool.py", line 787, in urlopen
    retries = retries.increment(
  File "C:\web_projects\arbitrage_kw\venv\lib\site-packages\urllib3\util\retry.py", line 550, in increment
    raise six.reraise(type(error), error, _stacktrace)
  File "C:\web_projects\arbitrage_kw\venv\lib\site-packages\urllib3\packages\six.py", line 769, in reraise
    raise value.with_traceback(tb)
  File "C:\web_projects\arbitrage_kw\venv\lib\site-packages\urllib3\connectionpool.py", line 703, in urlopen
    httplib_response = self._make_request(
  File "C:\web_projects\arbitrage_kw\venv\lib\site-packages\urllib3\connectionpool.py", line 449, in _make_request
    six.raise_from(e, None)
  File "<string>", line 3, in raise_from
  File "C:\web_projects\arbitrage_kw\venv\lib\site-packages\urllib3\connectionpool.py", line 444, in _make_request
    httplib_response = conn.getresponse()
  File "C:\Python310\lib\http\client.py", line 1374, in getresponse
    response.begin()
  File "C:\Python310\lib\http\client.py", line 318, in begin
    version, status, reason = self._read_status()
  File "C:\Python310\lib\http\client.py", line 279, in _read_status
    line = str(self.fp.readline(_MAXLINE + 1), "iso-8859-1")
  File "C:\Python310\lib\socket.py", line 705, in readinto
    return self._sock.recv_into(b)
urllib3.exceptions.ProtocolError: ('Connection aborted.', ConnectionResetError(10054, 'Удаленный хост принудительно разорвал существующее подключение', None, 10054, None))
2022-11-02 20:55:08,313 - my_application - ERROR - 'MainWidget' object has no attribute 'set_text'
Traceback (most recent call last):
  File "C:\web_projects\arbitrage_kw\main.py", line 10, in <module>
    widget = MainWidget()
  File "C:\web_projects\arbitrage_kw\main_widget.py", line 26, in __init__
    self.start.clicked.connect(self.set_text)
AttributeError: 'MainWidget' object has no attribute 'set_text'
2022-11-02 20:55:11,635 - my_application - ERROR - 'MainWidget' object has no attribute 'set_text'
Traceback (most recent call last):
  File "C:\web_projects\arbitrage_kw\main.py", line 10, in <module>
    widget = MainWidget()
  File "C:\web_projects\arbitrage_kw\main_widget.py", line 26, in __init__
    self.start.clicked.connect(self.set_text)
AttributeError: 'MainWidget' object has no attribute 'set_text'
2022-11-02 20:56:31,787 - my_application - ERROR - 'MainWidget' object has no attribute 'set_text'
Traceback (most recent call last):
  File "C:\web_projects\arbitrage_kw\main.py", line 10, in <module>
    widget = MainWidget()
  File "C:\web_projects\arbitrage_kw\main_widget.py", line 26, in __init__
    self.start.clicked.connect(self.set_text)
AttributeError: 'MainWidget' object has no attribute 'set_text'
2022-11-02 20:56:43,355 - my_application - ERROR - 'MainWidget' object has no attribute 'set_text'
Traceback (most recent call last):
  File "C:\web_projects\arbitrage_kw\main.py", line 10, in <module>
    widget = MainWidget()
  File "C:\web_projects\arbitrage_kw\main_widget.py", line 26, in __init__
    self.start.clicked.connect(self.set_text)
AttributeError: 'MainWidget' object has no attribute 'set_text'
2022-11-02 21:02:25,628 - my_application - ERROR - HTTPConnectionPool(host='localhost', port=15446): Max retries exceeded with url: /session/17e3777cb258e2c12e0f18cb8f35771e/window (Caused by NewConnectionError('<urllib3.connection.HTTPConnection object at 0x00000200DD74F0D0>: Failed to establish a new connection: [WinError 10061] Подключение не установлено, т.к. конечный компьютер отверг запрос на подключение'))
Traceback (most recent call last):
  File "C:\web_projects\arbitrage_kw\venv\lib\site-packages\urllib3\connection.py", line 174, in _new_conn
    conn = connection.create_connection(
  File "C:\web_projects\arbitrage_kw\venv\lib\site-packages\urllib3\util\connection.py", line 95, in create_connection
    raise err
  File "C:\web_projects\arbitrage_kw\venv\lib\site-packages\urllib3\util\connection.py", line 85, in create_connection
    sock.connect(sa)
ConnectionRefusedError: [WinError 10061] Подключение не установлено, т.к. конечный компьютер отверг запрос на подключение

During handling of the above exception, another exception occurred:

Traceback (most recent call last):
  File "C:\web_projects\arbitrage_kw\venv\lib\site-packages\urllib3\connectionpool.py", line 703, in urlopen
    httplib_response = self._make_request(
  File "C:\web_projects\arbitrage_kw\venv\lib\site-packages\urllib3\connectionpool.py", line 398, in _make_request
    conn.request(method, url, **httplib_request_kw)
  File "C:\web_projects\arbitrage_kw\venv\lib\site-packages\urllib3\connection.py", line 239, in request
    super(HTTPConnection, self).request(method, url, body=body, headers=headers)
  File "C:\Python310\lib\http\client.py", line 1282, in request
    self._send_request(method, url, body, headers, encode_chunked)
  File "C:\Python310\lib\http\client.py", line 1328, in _send_request
    self.endheaders(body, encode_chunked=encode_chunked)
  File "C:\Python310\lib\http\client.py", line 1277, in endheaders
    self._send_output(message_body, encode_chunked=encode_chunked)
  File "C:\Python310\lib\http\client.py", line 1037, in _send_output
    self.send(msg)
  File "C:\Python310\lib\http\client.py", line 975, in send
    self.connect()
  File "C:\web_projects\arbitrage_kw\venv\lib\site-packages\urllib3\connection.py", line 205, in connect
    conn = self._new_conn()
  File "C:\web_projects\arbitrage_kw\venv\lib\site-packages\urllib3\connection.py", line 186, in _new_conn
    raise NewConnectionError(
urllib3.exceptions.NewConnectionError: <urllib3.connection.HTTPConnection object at 0x00000200DD74F0D0>: Failed to establish a new connection: [WinError 10061] Подключение не установлено, т.к. конечный компьютер отверг запрос на подключение

During handling of the above exception, another exception occurred:

Traceback (most recent call last):
  File "C:\web_projects\arbitrage_kw\main_widget.py", line 126, in run
    self.br.run_script()
  File "C:\web_projects\arbitrage_kw\script_instance.py", line 36, in run_script
    self.all_games_ready = self.open_tab_for_each(games)
  File "C:\web_projects\arbitrage_kw\script_instance.py", line 65, in open_tab_for_each
    self.driver.close()
  File "C:\web_projects\arbitrage_kw\venv\lib\site-packages\selenium\webdriver\remote\webdriver.py", line 551, in close
    self.execute(Command.CLOSE)
  File "C:\web_projects\arbitrage_kw\venv\lib\site-packages\selenium\webdriver\remote\webdriver.py", line 427, in execute
    response = self.command_executor.execute(driver_command, params)
  File "C:\web_projects\arbitrage_kw\venv\lib\site-packages\selenium\webdriver\remote\remote_connection.py", line 344, in execute
    return self._request(command_info[0], url, body=data)
  File "C:\web_projects\arbitrage_kw\venv\lib\site-packages\selenium\webdriver\remote\remote_connection.py", line 366, in _request
    response = self._conn.request(method, url, body=body, headers=headers)
  File "C:\web_projects\arbitrage_kw\venv\lib\site-packages\urllib3\request.py", line 74, in request
    return self.request_encode_url(
  File "C:\web_projects\arbitrage_kw\venv\lib\site-packages\urllib3\request.py", line 96, in request_encode_url
    return self.urlopen(method, url, **extra_kw)
  File "C:\web_projects\arbitrage_kw\venv\lib\site-packages\urllib3\poolmanager.py", line 376, in urlopen
    response = conn.urlopen(method, u.request_uri, **kw)
  File "C:\web_projects\arbitrage_kw\venv\lib\site-packages\urllib3\connectionpool.py", line 815, in urlopen
    return self.urlopen(
  File "C:\web_projects\arbitrage_kw\venv\lib\site-packages\urllib3\connectionpool.py", line 815, in urlopen
    return self.urlopen(
  File "C:\web_projects\arbitrage_kw\venv\lib\site-packages\urllib3\connectionpool.py", line 815, in urlopen
    return self.urlopen(
  File "C:\web_projects\arbitrage_kw\venv\lib\site-packages\urllib3\connectionpool.py", line 787, in urlopen
    retries = retries.increment(
  File "C:\web_projects\arbitrage_kw\venv\lib\site-packages\urllib3\util\retry.py", line 592, in increment
    raise MaxRetryError(_pool, url, error or ResponseError(cause))
urllib3.exceptions.MaxRetryError: HTTPConnectionPool(host='localhost', port=15446): Max retries exceeded with url: /session/17e3777cb258e2c12e0f18cb8f35771e/window (Caused by NewConnectionError('<urllib3.connection.HTTPConnection object at 0x00000200DD74F0D0>: Failed to establish a new connection: [WinError 10061] Подключение не установлено, т.к. конечный компьютер отверг запрос на подключение'))
2022-11-02 21:04:28,502 - my_application - ERROR - ('Connection aborted.', ConnectionResetError(10054, 'Удаленный хост принудительно разорвал существующее подключение', None, 10054, None))
Traceback (most recent call last):
  File "C:\web_projects\arbitrage_kw\venv\lib\site-packages\urllib3\connectionpool.py", line 703, in urlopen
    httplib_response = self._make_request(
  File "C:\web_projects\arbitrage_kw\venv\lib\site-packages\urllib3\connectionpool.py", line 449, in _make_request
    six.raise_from(e, None)
  File "<string>", line 3, in raise_from
  File "C:\web_projects\arbitrage_kw\venv\lib\site-packages\urllib3\connectionpool.py", line 444, in _make_request
    httplib_response = conn.getresponse()
  File "C:\Python310\lib\http\client.py", line 1374, in getresponse
    response.begin()
  File "C:\Python310\lib\http\client.py", line 318, in begin
    version, status, reason = self._read_status()
  File "C:\Python310\lib\http\client.py", line 279, in _read_status
    line = str(self.fp.readline(_MAXLINE + 1), "iso-8859-1")
  File "C:\Python310\lib\socket.py", line 705, in readinto
    return self._sock.recv_into(b)
ConnectionResetError: [WinError 10054] Удаленный хост принудительно разорвал существующее подключение

During handling of the above exception, another exception occurred:

Traceback (most recent call last):
  File "C:\web_projects\arbitrage_kw\main_widget.py", line 126, in run
    self.br.run_script()
  File "C:\web_projects\arbitrage_kw\script_instance.py", line 31, in run_script
    self.driver.get('https://leon.bet/ru/live/soccer')
  File "C:\web_projects\arbitrage_kw\venv\lib\site-packages\selenium\webdriver\remote\webdriver.py", line 441, in get
    self.execute(Command.GET, {'url': url})
  File "C:\web_projects\arbitrage_kw\venv\lib\site-packages\selenium\webdriver\remote\webdriver.py", line 427, in execute
    response = self.command_executor.execute(driver_command, params)
  File "C:\web_projects\arbitrage_kw\venv\lib\site-packages\selenium\webdriver\remote\remote_connection.py", line 344, in execute
    return self._request(command_info[0], url, body=data)
  File "C:\web_projects\arbitrage_kw\venv\lib\site-packages\selenium\webdriver\remote\remote_connection.py", line 366, in _request
    response = self._conn.request(method, url, body=body, headers=headers)
  File "C:\web_projects\arbitrage_kw\venv\lib\site-packages\urllib3\request.py", line 78, in request
    return self.request_encode_body(
  File "C:\web_projects\arbitrage_kw\venv\lib\site-packages\urllib3\request.py", line 170, in request_encode_body
    return self.urlopen(method, url, **extra_kw)
  File "C:\web_projects\arbitrage_kw\venv\lib\site-packages\urllib3\poolmanager.py", line 376, in urlopen
    response = conn.urlopen(method, u.request_uri, **kw)
  File "C:\web_projects\arbitrage_kw\venv\lib\site-packages\urllib3\connectionpool.py", line 787, in urlopen
    retries = retries.increment(
  File "C:\web_projects\arbitrage_kw\venv\lib\site-packages\urllib3\util\retry.py", line 550, in increment
    raise six.reraise(type(error), error, _stacktrace)
  File "C:\web_projects\arbitrage_kw\venv\lib\site-packages\urllib3\packages\six.py", line 769, in reraise
    raise value.with_traceback(tb)
  File "C:\web_projects\arbitrage_kw\venv\lib\site-packages\urllib3\connectionpool.py", line 703, in urlopen
    httplib_response = self._make_request(
  File "C:\web_projects\arbitrage_kw\venv\lib\site-packages\urllib3\connectionpool.py", line 449, in _make_request
    six.raise_from(e, None)
  File "<string>", line 3, in raise_from
  File "C:\web_projects\arbitrage_kw\venv\lib\site-packages\urllib3\connectionpool.py", line 444, in _make_request
    httplib_response = conn.getresponse()
  File "C:\Python310\lib\http\client.py", line 1374, in getresponse
    response.begin()
  File "C:\Python310\lib\http\client.py", line 318, in begin
    version, status, reason = self._read_status()
  File "C:\Python310\lib\http\client.py", line 279, in _read_status
    line = str(self.fp.readline(_MAXLINE + 1), "iso-8859-1")
  File "C:\Python310\lib\socket.py", line 705, in readinto
    return self._sock.recv_into(b)
urllib3.exceptions.ProtocolError: ('Connection aborted.', ConnectionResetError(10054, 'Удаленный хост принудительно разорвал существующее подключение', None, 10054, None))
2022-11-02 21:54:04,314 - my_application - ERROR - Message: 'chromedriver' executable needs to be in PATH. Please see https://chromedriver.chromium.org/home
Traceback (most recent call last):
  File "C:\web_projects\arbitrage_kw\venv\lib\site-packages\selenium\webdriver\common\service.py", line 71, in start
    self.process = subprocess.Popen(cmd, env=self.env,
  File "C:\Python310\lib\subprocess.py", line 969, in __init__
    self._execute_child(args, executable, preexec_fn, close_fds,
  File "C:\Python310\lib\subprocess.py", line 1438, in _execute_child
    hp, ht, pid, tid = _winapi.CreateProcess(executable, args,
FileNotFoundError: [WinError 2] Не удается найти указанный файл

During handling of the above exception, another exception occurred:

Traceback (most recent call last):
  File "C:\web_projects\arbitrage_kw\main_widget.py", line 131, in run
    webdriver.Chrome(service=service, options=options, executable_path=os.path.join('browser', '.wdm', 'drivers', 'chromedriver', 'win32', '106.0.5249',
  File "C:\web_projects\arbitrage_kw\venv\lib\site-packages\selenium\webdriver\chrome\webdriver.py", line 69, in __init__
    super().__init__(DesiredCapabilities.CHROME['browserName'], "goog",
  File "C:\web_projects\arbitrage_kw\venv\lib\site-packages\selenium\webdriver\chromium\webdriver.py", line 89, in __init__
    self.service.start()
  File "C:\web_projects\arbitrage_kw\venv\lib\site-packages\selenium\webdriver\common\service.py", line 81, in start
    raise WebDriverException(
selenium.common.exceptions.WebDriverException: Message: 'chromedriver' executable needs to be in PATH. Please see https://chromedriver.chromium.org/home

2022-11-02 21:54:51,799 - my_application - ERROR - Message: 'chromedriver' executable needs to be in PATH. Please see https://chromedriver.chromium.org/home
Traceback (most recent call last):
  File "C:\web_projects\arbitrage_kw\venv\lib\site-packages\selenium\webdriver\common\service.py", line 71, in start
    self.process = subprocess.Popen(cmd, env=self.env,
  File "C:\Python310\lib\subprocess.py", line 969, in __init__
    self._execute_child(args, executable, preexec_fn, close_fds,
  File "C:\Python310\lib\subprocess.py", line 1438, in _execute_child
    hp, ht, pid, tid = _winapi.CreateProcess(executable, args,
FileNotFoundError: [WinError 2] Не удается найти указанный файл

During handling of the above exception, another exception occurred:

Traceback (most recent call last):
  File "C:\web_projects\arbitrage_kw\main_widget.py", line 131, in run
    webdriver.Chrome(service=service, options=options, executable_path=os.path.join('browser', '.wdm', 'drivers', 'chromedriver', 'win32', '106.0.5249',
  File "C:\web_projects\arbitrage_kw\venv\lib\site-packages\selenium\webdriver\chrome\webdriver.py", line 69, in __init__
    super().__init__(DesiredCapabilities.CHROME['browserName'], "goog",
  File "C:\web_projects\arbitrage_kw\venv\lib\site-packages\selenium\webdriver\chromium\webdriver.py", line 89, in __init__
    self.service.start()
  File "C:\web_projects\arbitrage_kw\venv\lib\site-packages\selenium\webdriver\common\service.py", line 81, in start
    raise WebDriverException(
selenium.common.exceptions.WebDriverException: Message: 'chromedriver' executable needs to be in PATH. Please see https://chromedriver.chromium.org/home

2022-11-02 21:59:46,535 - my_application - ERROR - Message: 
Stacktrace:
Backtrace:
	Ordinal0 [0x009F1ED3+2236115]
	Ordinal0 [0x009892F1+1807089]
	Ordinal0 [0x008966FD+812797]
	Ordinal0 [0x008C55DF+1005023]
	Ordinal0 [0x008C57CB+1005515]
	Ordinal0 [0x008F7632+1209906]
	Ordinal0 [0x008E1AD4+1120980]
	Ordinal0 [0x008F59E2+1202658]
	Ordinal0 [0x008E18A6+1120422]
	Ordinal0 [0x008BA73D+960317]
	Ordinal0 [0x008BB71F+964383]
	GetHandleVerifier [0x00C9E7E2+2743074]
	GetHandleVerifier [0x00C908D4+2685972]
	GetHandleVerifier [0x00A82BAA+532202]
	GetHandleVerifier [0x00A81990+527568]
	Ordinal0 [0x0099080C+1837068]
	Ordinal0 [0x00994CD8+1854680]
	Ordinal0 [0x00994DC5+1854917]
	Ordinal0 [0x0099ED64+1895780]
	BaseThreadInitThunk [0x7694FA29+25]
	RtlGetAppContainerNamedObjectPath [0x77677BBE+286]
	RtlGetAppContainerNamedObjectPath [0x77677B8E+238]
Traceback (most recent call last):
  File "C:\web_projects\arbitrage_kw\main_widget.py", line 137, in run
    self.br.run_script()
  File "C:\web_projects\arbitrage_kw\script_instance.py", line 33, in run_script
    table = self.locate_element(self.ENTIRE_TABLE)
  File "C:\web_projects\arbitrage_kw\base_methods.py", line 13, in locate_element
    locate: WebElement = WebDriverWait(self.driver, 10).until(EC.element_to_be_clickable(locator))
  File "C:\web_projects\arbitrage_kw\venv\lib\site-packages\selenium\webdriver\support\wait.py", line 90, in until
    raise TimeoutException(message, screen, stacktrace)
selenium.common.exceptions.TimeoutException: Message: 
Stacktrace:
Backtrace:
	Ordinal0 [0x009F1ED3+2236115]
	Ordinal0 [0x009892F1+1807089]
	Ordinal0 [0x008966FD+812797]
	Ordinal0 [0x008C55DF+1005023]
	Ordinal0 [0x008C57CB+1005515]
	Ordinal0 [0x008F7632+1209906]
	Ordinal0 [0x008E1AD4+1120980]
	Ordinal0 [0x008F59E2+1202658]
	Ordinal0 [0x008E18A6+1120422]
	Ordinal0 [0x008BA73D+960317]
	Ordinal0 [0x008BB71F+964383]
	GetHandleVerifier [0x00C9E7E2+2743074]
	GetHandleVerifier [0x00C908D4+2685972]
	GetHandleVerifier [0x00A82BAA+532202]
	GetHandleVerifier [0x00A81990+527568]
	Ordinal0 [0x0099080C+1837068]
	Ordinal0 [0x00994CD8+1854680]
	Ordinal0 [0x00994DC5+1854917]
	Ordinal0 [0x0099ED64+1895780]
	BaseThreadInitThunk [0x7694FA29+25]
	RtlGetAppContainerNamedObjectPath [0x77677BBE+286]
	RtlGetAppContainerNamedObjectPath [0x77677B8E+238]

2022-11-02 22:01:25,845 - my_application - ERROR - Message: unknown error: net::ERR_CONNECTION_RESET
  (Session info: headless chrome=106.0.5249.121)
Stacktrace:
Backtrace:
	Ordinal0 [0x00A01ED3+2236115]
	Ordinal0 [0x009992F1+1807089]
	Ordinal0 [0x008A66FD+812797]
	Ordinal0 [0x008A2C42+797762]
	Ordinal0 [0x00899C1D+760861]
	Ordinal0 [0x0089A9FC+764412]
	Ordinal0 [0x00899E5F+761439]
	Ordinal0 [0x00899350+758608]
	Ordinal0 [0x008992C1+758465]
	Ordinal0 [0x00898113+753939]
	Ordinal0 [0x0089861D+755229]
	Ordinal0 [0x008A800E+819214]
	Ordinal0 [0x009060CD+1204429]
	Ordinal0 [0x008F1A8C+1120908]
	Ordinal0 [0x009059E2+1202658]
	Ordinal0 [0x008F18A6+1120422]
	Ordinal0 [0x008CA73D+960317]
	Ordinal0 [0x008CB71F+964383]
	GetHandleVerifier [0x00CAE7E2+2743074]
	GetHandleVerifier [0x00CA08D4+2685972]
	GetHandleVerifier [0x00A92BAA+532202]
	GetHandleVerifier [0x00A91990+527568]
	Ordinal0 [0x009A080C+1837068]
	Ordinal0 [0x009A4CD8+1854680]
	Ordinal0 [0x009A4DC5+1854917]
	Ordinal0 [0x009AED64+1895780]
	BaseThreadInitThunk [0x7694FA29+25]
	RtlGetAppContainerNamedObjectPath [0x77677BBE+286]
	RtlGetAppContainerNamedObjectPath [0x77677B8E+238]
Traceback (most recent call last):
  File "C:\web_projects\arbitrage_kw\main_widget.py", line 137, in run
    self.br.run_script()
  File "C:\web_projects\arbitrage_kw\script_instance.py", line 31, in run_script
    self.driver.get('https://leon.bet/ru/live/soccer')
  File "C:\web_projects\arbitrage_kw\venv\lib\site-packages\selenium\webdriver\remote\webdriver.py", line 441, in get
    self.execute(Command.GET, {'url': url})
  File "C:\web_projects\arbitrage_kw\venv\lib\site-packages\selenium\webdriver\remote\webdriver.py", line 429, in execute
    self.error_handler.check_response(response)
  File "C:\web_projects\arbitrage_kw\venv\lib\site-packages\selenium\webdriver\remote\errorhandler.py", line 243, in check_response
    raise exception_class(message, screen, stacktrace)
selenium.common.exceptions.WebDriverException: Message: unknown error: net::ERR_CONNECTION_RESET
  (Session info: headless chrome=106.0.5249.121)
Stacktrace:
Backtrace:
	Ordinal0 [0x00A01ED3+2236115]
	Ordinal0 [0x009992F1+1807089]
	Ordinal0 [0x008A66FD+812797]
	Ordinal0 [0x008A2C42+797762]
	Ordinal0 [0x00899C1D+760861]
	Ordinal0 [0x0089A9FC+764412]
	Ordinal0 [0x00899E5F+761439]
	Ordinal0 [0x00899350+758608]
	Ordinal0 [0x008992C1+758465]
	Ordinal0 [0x00898113+753939]
	Ordinal0 [0x0089861D+755229]
	Ordinal0 [0x008A800E+819214]
	Ordinal0 [0x009060CD+1204429]
	Ordinal0 [0x008F1A8C+1120908]
	Ordinal0 [0x009059E2+1202658]
	Ordinal0 [0x008F18A6+1120422]
	Ordinal0 [0x008CA73D+960317]
	Ordinal0 [0x008CB71F+964383]
	GetHandleVerifier [0x00CAE7E2+2743074]
	GetHandleVerifier [0x00CA08D4+2685972]
	GetHandleVerifier [0x00A92BAA+532202]
	GetHandleVerifier [0x00A91990+527568]
	Ordinal0 [0x009A080C+1837068]
	Ordinal0 [0x009A4CD8+1854680]
	Ordinal0 [0x009A4DC5+1854917]
	Ordinal0 [0x009AED64+1895780]
	BaseThreadInitThunk [0x7694FA29+25]
	RtlGetAppContainerNamedObjectPath [0x77677BBE+286]
	RtlGetAppContainerNamedObjectPath [0x77677B8E+238]

2022-11-02 22:03:59,945 - my_application - ERROR - Message: unknown error: net::ERR_CONNECTION_RESET
  (Session info: headless chrome=106.0.5249.121)
Stacktrace:
Backtrace:
	Ordinal0 [0x00A01ED3+2236115]
	Ordinal0 [0x009992F1+1807089]
	Ordinal0 [0x008A66FD+812797]
	Ordinal0 [0x008A2C42+797762]
	Ordinal0 [0x00899C1D+760861]
	Ordinal0 [0x0089A9FC+764412]
	Ordinal0 [0x00899E5F+761439]
	Ordinal0 [0x00899350+758608]
	Ordinal0 [0x008992C1+758465]
	Ordinal0 [0x00898113+753939]
	Ordinal0 [0x0089861D+755229]
	Ordinal0 [0x008A800E+819214]
	Ordinal0 [0x009060CD+1204429]
	Ordinal0 [0x008F1A8C+1120908]
	Ordinal0 [0x009059E2+1202658]
	Ordinal0 [0x008F18A6+1120422]
	Ordinal0 [0x008CA73D+960317]
	Ordinal0 [0x008CB71F+964383]
	GetHandleVerifier [0x00CAE7E2+2743074]
	GetHandleVerifier [0x00CA08D4+2685972]
	GetHandleVerifier [0x00A92BAA+532202]
	GetHandleVerifier [0x00A91990+527568]
	Ordinal0 [0x009A080C+1837068]
	Ordinal0 [0x009A4CD8+1854680]
	Ordinal0 [0x009A4DC5+1854917]
	Ordinal0 [0x009AED64+1895780]
	BaseThreadInitThunk [0x7694FA29+25]
	RtlGetAppContainerNamedObjectPath [0x77677BBE+286]
	RtlGetAppContainerNamedObjectPath [0x77677B8E+238]
Traceback (most recent call last):
  File "C:\web_projects\arbitrage_kw\main_widget.py", line 137, in run
    self.br.run_script()
  File "C:\web_projects\arbitrage_kw\script_instance.py", line 31, in run_script
    self.driver.get('https://leon.bet/ru/live/soccer')
  File "C:\web_projects\arbitrage_kw\venv\lib\site-packages\selenium\webdriver\remote\webdriver.py", line 441, in get
    self.execute(Command.GET, {'url': url})
  File "C:\web_projects\arbitrage_kw\venv\lib\site-packages\selenium\webdriver\remote\webdriver.py", line 429, in execute
    self.error_handler.check_response(response)
  File "C:\web_projects\arbitrage_kw\venv\lib\site-packages\selenium\webdriver\remote\errorhandler.py", line 243, in check_response
    raise exception_class(message, screen, stacktrace)
selenium.common.exceptions.WebDriverException: Message: unknown error: net::ERR_CONNECTION_RESET
  (Session info: headless chrome=106.0.5249.121)
Stacktrace:
Backtrace:
	Ordinal0 [0x00A01ED3+2236115]
	Ordinal0 [0x009992F1+1807089]
	Ordinal0 [0x008A66FD+812797]
	Ordinal0 [0x008A2C42+797762]
	Ordinal0 [0x00899C1D+760861]
	Ordinal0 [0x0089A9FC+764412]
	Ordinal0 [0x00899E5F+761439]
	Ordinal0 [0x00899350+758608]
	Ordinal0 [0x008992C1+758465]
	Ordinal0 [0x00898113+753939]
	Ordinal0 [0x0089861D+755229]
	Ordinal0 [0x008A800E+819214]
	Ordinal0 [0x009060CD+1204429]
	Ordinal0 [0x008F1A8C+1120908]
	Ordinal0 [0x009059E2+1202658]
	Ordinal0 [0x008F18A6+1120422]
	Ordinal0 [0x008CA73D+960317]
	Ordinal0 [0x008CB71F+964383]
	GetHandleVerifier [0x00CAE7E2+2743074]
	GetHandleVerifier [0x00CA08D4+2685972]
	GetHandleVerifier [0x00A92BAA+532202]
	GetHandleVerifier [0x00A91990+527568]
	Ordinal0 [0x009A080C+1837068]
	Ordinal0 [0x009A4CD8+1854680]
	Ordinal0 [0x009A4DC5+1854917]
	Ordinal0 [0x009AED64+1895780]
	BaseThreadInitThunk [0x7694FA29+25]
	RtlGetAppContainerNamedObjectPath [0x77677BBE+286]
	RtlGetAppContainerNamedObjectPath [0x77677B8E+238]

2022-11-02 22:04:17,052 - my_application - ERROR - Message: unknown error: net::ERR_CONNECTION_RESET
  (Session info: headless chrome=106.0.5249.121)
Stacktrace:
Backtrace:
	Ordinal0 [0x00A01ED3+2236115]
	Ordinal0 [0x009992F1+1807089]
	Ordinal0 [0x008A66FD+812797]
	Ordinal0 [0x008A2C42+797762]
	Ordinal0 [0x00899C1D+760861]
	Ordinal0 [0x0089A9FC+764412]
	Ordinal0 [0x00899E5F+761439]
	Ordinal0 [0x00899350+758608]
	Ordinal0 [0x008992C1+758465]
	Ordinal0 [0x00898113+753939]
	Ordinal0 [0x0089861D+755229]
	Ordinal0 [0x008A800E+819214]
	Ordinal0 [0x009060CD+1204429]
	Ordinal0 [0x008F1A8C+1120908]
	Ordinal0 [0x009059E2+1202658]
	Ordinal0 [0x008F18A6+1120422]
	Ordinal0 [0x008CA73D+960317]
	Ordinal0 [0x008CB71F+964383]
	GetHandleVerifier [0x00CAE7E2+2743074]
	GetHandleVerifier [0x00CA08D4+2685972]
	GetHandleVerifier [0x00A92BAA+532202]
	GetHandleVerifier [0x00A91990+527568]
	Ordinal0 [0x009A080C+1837068]
	Ordinal0 [0x009A4CD8+1854680]
	Ordinal0 [0x009A4DC5+1854917]
	Ordinal0 [0x009AED64+1895780]
	BaseThreadInitThunk [0x7694FA29+25]
	RtlGetAppContainerNamedObjectPath [0x77677BBE+286]
	RtlGetAppContainerNamedObjectPath [0x77677B8E+238]
Traceback (most recent call last):
  File "C:\web_projects\arbitrage_kw\main_widget.py", line 137, in run
    self.br.run_script()
  File "C:\web_projects\arbitrage_kw\script_instance.py", line 31, in run_script
    self.driver.get('https://leon.bet/ru/live/soccer')
  File "C:\web_projects\arbitrage_kw\venv\lib\site-packages\selenium\webdriver\remote\webdriver.py", line 441, in get
    self.execute(Command.GET, {'url': url})
  File "C:\web_projects\arbitrage_kw\venv\lib\site-packages\selenium\webdriver\remote\webdriver.py", line 429, in execute
    self.error_handler.check_response(response)
  File "C:\web_projects\arbitrage_kw\venv\lib\site-packages\selenium\webdriver\remote\errorhandler.py", line 243, in check_response
    raise exception_class(message, screen, stacktrace)
selenium.common.exceptions.WebDriverException: Message: unknown error: net::ERR_CONNECTION_RESET
  (Session info: headless chrome=106.0.5249.121)
Stacktrace:
Backtrace:
	Ordinal0 [0x00A01ED3+2236115]
	Ordinal0 [0x009992F1+1807089]
	Ordinal0 [0x008A66FD+812797]
	Ordinal0 [0x008A2C42+797762]
	Ordinal0 [0x00899C1D+760861]
	Ordinal0 [0x0089A9FC+764412]
	Ordinal0 [0x00899E5F+761439]
	Ordinal0 [0x00899350+758608]
	Ordinal0 [0x008992C1+758465]
	Ordinal0 [0x00898113+753939]
	Ordinal0 [0x0089861D+755229]
	Ordinal0 [0x008A800E+819214]
	Ordinal0 [0x009060CD+1204429]
	Ordinal0 [0x008F1A8C+1120908]
	Ordinal0 [0x009059E2+1202658]
	Ordinal0 [0x008F18A6+1120422]
	Ordinal0 [0x008CA73D+960317]
	Ordinal0 [0x008CB71F+964383]
	GetHandleVerifier [0x00CAE7E2+2743074]
	GetHandleVerifier [0x00CA08D4+2685972]
	GetHandleVerifier [0x00A92BAA+532202]
	GetHandleVerifier [0x00A91990+527568]
	Ordinal0 [0x009A080C+1837068]
	Ordinal0 [0x009A4CD8+1854680]
	Ordinal0 [0x009A4DC5+1854917]
	Ordinal0 [0x009AED64+1895780]
	BaseThreadInitThunk [0x7694FA29+25]
	RtlGetAppContainerNamedObjectPath [0x77677BBE+286]
	RtlGetAppContainerNamedObjectPath [0x77677B8E+238]

2022-11-02 22:05:13,413 - my_application - ERROR - Message: unknown error: net::ERR_CONNECTION_RESET
  (Session info: headless chrome=106.0.5249.121)
Stacktrace:
Backtrace:
	Ordinal0 [0x00A01ED3+2236115]
	Ordinal0 [0x009992F1+1807089]
	Ordinal0 [0x008A66FD+812797]
	Ordinal0 [0x008A2C42+797762]
	Ordinal0 [0x00899C1D+760861]
	Ordinal0 [0x0089A9FC+764412]
	Ordinal0 [0x00899E5F+761439]
	Ordinal0 [0x00899350+758608]
	Ordinal0 [0x008992C1+758465]
	Ordinal0 [0x00898113+753939]
	Ordinal0 [0x0089861D+755229]
	Ordinal0 [0x008A800E+819214]
	Ordinal0 [0x009060CD+1204429]
	Ordinal0 [0x008F1A8C+1120908]
	Ordinal0 [0x009059E2+1202658]
	Ordinal0 [0x008F18A6+1120422]
	Ordinal0 [0x008CA73D+960317]
	Ordinal0 [0x008CB71F+964383]
	GetHandleVerifier [0x00CAE7E2+2743074]
	GetHandleVerifier [0x00CA08D4+2685972]
	GetHandleVerifier [0x00A92BAA+532202]
	GetHandleVerifier [0x00A91990+527568]
	Ordinal0 [0x009A080C+1837068]
	Ordinal0 [0x009A4CD8+1854680]
	Ordinal0 [0x009A4DC5+1854917]
	Ordinal0 [0x009AED64+1895780]
	BaseThreadInitThunk [0x7694FA29+25]
	RtlGetAppContainerNamedObjectPath [0x77677BBE+286]
	RtlGetAppContainerNamedObjectPath [0x77677B8E+238]
Traceback (most recent call last):
  File "C:\web_projects\arbitrage_kw\main_widget.py", line 137, in run
    self.br.run_script()
  File "C:\web_projects\arbitrage_kw\script_instance.py", line 31, in run_script
    self.driver.get('https://leon.bet/ru/live/soccer')
  File "C:\web_projects\arbitrage_kw\venv\lib\site-packages\selenium\webdriver\remote\webdriver.py", line 441, in get
    self.execute(Command.GET, {'url': url})
  File "C:\web_projects\arbitrage_kw\venv\lib\site-packages\selenium\webdriver\remote\webdriver.py", line 429, in execute
    self.error_handler.check_response(response)
  File "C:\web_projects\arbitrage_kw\venv\lib\site-packages\selenium\webdriver\remote\errorhandler.py", line 243, in check_response
    raise exception_class(message, screen, stacktrace)
selenium.common.exceptions.WebDriverException: Message: unknown error: net::ERR_CONNECTION_RESET
  (Session info: headless chrome=106.0.5249.121)
Stacktrace:
Backtrace:
	Ordinal0 [0x00A01ED3+2236115]
	Ordinal0 [0x009992F1+1807089]
	Ordinal0 [0x008A66FD+812797]
	Ordinal0 [0x008A2C42+797762]
	Ordinal0 [0x00899C1D+760861]
	Ordinal0 [0x0089A9FC+764412]
	Ordinal0 [0x00899E5F+761439]
	Ordinal0 [0x00899350+758608]
	Ordinal0 [0x008992C1+758465]
	Ordinal0 [0x00898113+753939]
	Ordinal0 [0x0089861D+755229]
	Ordinal0 [0x008A800E+819214]
	Ordinal0 [0x009060CD+1204429]
	Ordinal0 [0x008F1A8C+1120908]
	Ordinal0 [0x009059E2+1202658]
	Ordinal0 [0x008F18A6+1120422]
	Ordinal0 [0x008CA73D+960317]
	Ordinal0 [0x008CB71F+964383]
	GetHandleVerifier [0x00CAE7E2+2743074]
	GetHandleVerifier [0x00CA08D4+2685972]
	GetHandleVerifier [0x00A92BAA+532202]
	GetHandleVerifier [0x00A91990+527568]
	Ordinal0 [0x009A080C+1837068]
	Ordinal0 [0x009A4CD8+1854680]
	Ordinal0 [0x009A4DC5+1854917]
	Ordinal0 [0x009AED64+1895780]
	BaseThreadInitThunk [0x7694FA29+25]
	RtlGetAppContainerNamedObjectPath [0x77677BBE+286]
	RtlGetAppContainerNamedObjectPath [0x77677B8E+238]

2022-11-03 01:08:40,190 - my_application - ERROR - Message: 'browser' executable needs to be in PATH. Please see https://chromedriver.chromium.org/home
Traceback (most recent call last):
  File "C:\web_projects\arbitrage_kw\venv\lib\site-packages\selenium\webdriver\common\service.py", line 71, in start
    self.process = subprocess.Popen(cmd, env=self.env,
  File "C:\Python310\lib\subprocess.py", line 969, in __init__
    self._execute_child(args, executable, preexec_fn, close_fds,
  File "C:\Python310\lib\subprocess.py", line 1438, in _execute_child
    hp, ht, pid, tid = _winapi.CreateProcess(executable, args,
FileNotFoundError: [WinError 2] Не удается найти указанный файл

During handling of the above exception, another exception occurred:

Traceback (most recent call last):
  File "C:\web_projects\arbitrage_kw\main_widget.py", line 142, in run
    webdriver.Chrome(service=service, options=options))
  File "C:\web_projects\arbitrage_kw\venv\lib\site-packages\selenium\webdriver\chrome\webdriver.py", line 69, in __init__
    super().__init__(DesiredCapabilities.CHROME['browserName'], "goog",
  File "C:\web_projects\arbitrage_kw\venv\lib\site-packages\selenium\webdriver\chromium\webdriver.py", line 89, in __init__
    self.service.start()
  File "C:\web_projects\arbitrage_kw\venv\lib\site-packages\selenium\webdriver\common\service.py", line 81, in start
    raise WebDriverException(
selenium.common.exceptions.WebDriverException: Message: 'browser' executable needs to be in PATH. Please see https://chromedriver.chromium.org/home

2022-11-03 09:37:48,725 - my_application - ERROR - Message: unknown error: net::ERR_CONNECTION_RESET
  (Session info: headless chrome=107.0.5304.88)
Stacktrace:
Backtrace:
	Ordinal0 [0x007A1ED3+2236115]
	Ordinal0 [0x007392F1+1807089]
	Ordinal0 [0x006466FD+812797]
	Ordinal0 [0x00642C42+797762]
	Ordinal0 [0x00639C1D+760861]
	Ordinal0 [0x0063A9FC+764412]
	Ordinal0 [0x00639E5F+761439]
	Ordinal0 [0x00639350+758608]
	Ordinal0 [0x006392C1+758465]
	Ordinal0 [0x00638113+753939]
	Ordinal0 [0x0063861D+755229]
	Ordinal0 [0x0064800E+819214]
	Ordinal0 [0x006A60CD+1204429]
	Ordinal0 [0x00691A8C+1120908]
	Ordinal0 [0x006A59E2+1202658]
	Ordinal0 [0x006918A6+1120422]
	Ordinal0 [0x0066A73D+960317]
	Ordinal0 [0x0066B71F+964383]
	GetHandleVerifier [0x00A4E7E2+2743074]
	GetHandleVerifier [0x00A408D4+2685972]
	GetHandleVerifier [0x00832BAA+532202]
	GetHandleVerifier [0x00831990+527568]
	Ordinal0 [0x0074080C+1837068]
	Ordinal0 [0x00744CD8+1854680]
	Ordinal0 [0x00744DC5+1854917]
	Ordinal0 [0x0074ED64+1895780]
	BaseThreadInitThunk [0x75C1FA29+25]
	RtlGetAppContainerNamedObjectPath [0x77027BBE+286]
	RtlGetAppContainerNamedObjectPath [0x77027B8E+238]
Traceback (most recent call last):
  File "C:\web_projects\arbitrage_kw\main_widget.py", line 151, in run
    self.br.run_script()
  File "C:\web_projects\arbitrage_kw\script_instance.py", line 31, in run_script
    self.driver.get('https://leon.bet/ru/live/soccer')
  File "C:\web_projects\arbitrage_kw\venv\lib\site-packages\selenium\webdriver\remote\webdriver.py", line 441, in get
    self.execute(Command.GET, {'url': url})
  File "C:\web_projects\arbitrage_kw\venv\lib\site-packages\selenium\webdriver\remote\webdriver.py", line 429, in execute
    self.error_handler.check_response(response)
  File "C:\web_projects\arbitrage_kw\venv\lib\site-packages\selenium\webdriver\remote\errorhandler.py", line 243, in check_response
    raise exception_class(message, screen, stacktrace)
selenium.common.exceptions.WebDriverException: Message: unknown error: net::ERR_CONNECTION_RESET
  (Session info: headless chrome=107.0.5304.88)
Stacktrace:
Backtrace:
	Ordinal0 [0x007A1ED3+2236115]
	Ordinal0 [0x007392F1+1807089]
	Ordinal0 [0x006466FD+812797]
	Ordinal0 [0x00642C42+797762]
	Ordinal0 [0x00639C1D+760861]
	Ordinal0 [0x0063A9FC+764412]
	Ordinal0 [0x00639E5F+761439]
	Ordinal0 [0x00639350+758608]
	Ordinal0 [0x006392C1+758465]
	Ordinal0 [0x00638113+753939]
	Ordinal0 [0x0063861D+755229]
	Ordinal0 [0x0064800E+819214]
	Ordinal0 [0x006A60CD+1204429]
	Ordinal0 [0x00691A8C+1120908]
	Ordinal0 [0x006A59E2+1202658]
	Ordinal0 [0x006918A6+1120422]
	Ordinal0 [0x0066A73D+960317]
	Ordinal0 [0x0066B71F+964383]
	GetHandleVerifier [0x00A4E7E2+2743074]
	GetHandleVerifier [0x00A408D4+2685972]
	GetHandleVerifier [0x00832BAA+532202]
	GetHandleVerifier [0x00831990+527568]
	Ordinal0 [0x0074080C+1837068]
	Ordinal0 [0x00744CD8+1854680]
	Ordinal0 [0x00744DC5+1854917]
	Ordinal0 [0x0074ED64+1895780]
	BaseThreadInitThunk [0x75C1FA29+25]
	RtlGetAppContainerNamedObjectPath [0x77027BBE+286]
	RtlGetAppContainerNamedObjectPath [0x77027B8E+238]

2022-11-03 09:38:01,814 - my_application - ERROR - Message: unknown error: net::ERR_CONNECTION_RESET
  (Session info: headless chrome=107.0.5304.88)
Stacktrace:
Backtrace:
	Ordinal0 [0x007A1ED3+2236115]
	Ordinal0 [0x007392F1+1807089]
	Ordinal0 [0x006466FD+812797]
	Ordinal0 [0x00642C42+797762]
	Ordinal0 [0x00639C1D+760861]
	Ordinal0 [0x0063A9FC+764412]
	Ordinal0 [0x00639E5F+761439]
	Ordinal0 [0x00639350+758608]
	Ordinal0 [0x006392C1+758465]
	Ordinal0 [0x00638113+753939]
	Ordinal0 [0x0063861D+755229]
	Ordinal0 [0x0064800E+819214]
	Ordinal0 [0x006A60CD+1204429]
	Ordinal0 [0x00691A8C+1120908]
	Ordinal0 [0x006A59E2+1202658]
	Ordinal0 [0x006918A6+1120422]
	Ordinal0 [0x0066A73D+960317]
	Ordinal0 [0x0066B71F+964383]
	GetHandleVerifier [0x00A4E7E2+2743074]
	GetHandleVerifier [0x00A408D4+2685972]
	GetHandleVerifier [0x00832BAA+532202]
	GetHandleVerifier [0x00831990+527568]
	Ordinal0 [0x0074080C+1837068]
	Ordinal0 [0x00744CD8+1854680]
	Ordinal0 [0x00744DC5+1854917]
	Ordinal0 [0x0074ED64+1895780]
	BaseThreadInitThunk [0x75C1FA29+25]
	RtlGetAppContainerNamedObjectPath [0x77027BBE+286]
	RtlGetAppContainerNamedObjectPath [0x77027B8E+238]
Traceback (most recent call last):
  File "C:\web_projects\arbitrage_kw\main_widget.py", line 151, in run
    self.br.run_script()
  File "C:\web_projects\arbitrage_kw\script_instance.py", line 31, in run_script
    self.driver.get('https://leon.bet/ru/live/soccer')
  File "C:\web_projects\arbitrage_kw\venv\lib\site-packages\selenium\webdriver\remote\webdriver.py", line 441, in get
    self.execute(Command.GET, {'url': url})
  File "C:\web_projects\arbitrage_kw\venv\lib\site-packages\selenium\webdriver\remote\webdriver.py", line 429, in execute
    self.error_handler.check_response(response)
  File "C:\web_projects\arbitrage_kw\venv\lib\site-packages\selenium\webdriver\remote\errorhandler.py", line 243, in check_response
    raise exception_class(message, screen, stacktrace)
selenium.common.exceptions.WebDriverException: Message: unknown error: net::ERR_CONNECTION_RESET
  (Session info: headless chrome=107.0.5304.88)
Stacktrace:
Backtrace:
	Ordinal0 [0x007A1ED3+2236115]
	Ordinal0 [0x007392F1+1807089]
	Ordinal0 [0x006466FD+812797]
	Ordinal0 [0x00642C42+797762]
	Ordinal0 [0x00639C1D+760861]
	Ordinal0 [0x0063A9FC+764412]
	Ordinal0 [0x00639E5F+761439]
	Ordinal0 [0x00639350+758608]
	Ordinal0 [0x006392C1+758465]
	Ordinal0 [0x00638113+753939]
	Ordinal0 [0x0063861D+755229]
	Ordinal0 [0x0064800E+819214]
	Ordinal0 [0x006A60CD+1204429]
	Ordinal0 [0x00691A8C+1120908]
	Ordinal0 [0x006A59E2+1202658]
	Ordinal0 [0x006918A6+1120422]
	Ordinal0 [0x0066A73D+960317]
	Ordinal0 [0x0066B71F+964383]
	GetHandleVerifier [0x00A4E7E2+2743074]
	GetHandleVerifier [0x00A408D4+2685972]
	GetHandleVerifier [0x00832BAA+532202]
	GetHandleVerifier [0x00831990+527568]
	Ordinal0 [0x0074080C+1837068]
	Ordinal0 [0x00744CD8+1854680]
	Ordinal0 [0x00744DC5+1854917]
	Ordinal0 [0x0074ED64+1895780]
	BaseThreadInitThunk [0x75C1FA29+25]
	RtlGetAppContainerNamedObjectPath [0x77027BBE+286]
	RtlGetAppContainerNamedObjectPath [0x77027B8E+238]

2022-11-03 09:38:07,851 - my_application - ERROR - Message: unknown error: net::ERR_CONNECTION_RESET
  (Session info: headless chrome=107.0.5304.88)
Stacktrace:
Backtrace:
	Ordinal0 [0x007A1ED3+2236115]
	Ordinal0 [0x007392F1+1807089]
	Ordinal0 [0x006466FD+812797]
	Ordinal0 [0x00642C42+797762]
	Ordinal0 [0x00639C1D+760861]
	Ordinal0 [0x0063A9FC+764412]
	Ordinal0 [0x00639E5F+761439]
	Ordinal0 [0x00639350+758608]
	Ordinal0 [0x006392C1+758465]
	Ordinal0 [0x00638113+753939]
	Ordinal0 [0x0063861D+755229]
	Ordinal0 [0x0064800E+819214]
	Ordinal0 [0x006A60CD+1204429]
	Ordinal0 [0x00691A8C+1120908]
	Ordinal0 [0x006A59E2+1202658]
	Ordinal0 [0x006918A6+1120422]
	Ordinal0 [0x0066A73D+960317]
	Ordinal0 [0x0066B71F+964383]
	GetHandleVerifier [0x00A4E7E2+2743074]
	GetHandleVerifier [0x00A408D4+2685972]
	GetHandleVerifier [0x00832BAA+532202]
	GetHandleVerifier [0x00831990+527568]
	Ordinal0 [0x0074080C+1837068]
	Ordinal0 [0x00744CD8+1854680]
	Ordinal0 [0x00744DC5+1854917]
	Ordinal0 [0x0074ED64+1895780]
	BaseThreadInitThunk [0x75C1FA29+25]
	RtlGetAppContainerNamedObjectPath [0x77027BBE+286]
	RtlGetAppContainerNamedObjectPath [0x77027B8E+238]
Traceback (most recent call last):
  File "C:\web_projects\arbitrage_kw\main_widget.py", line 151, in run
    self.br.run_script()
  File "C:\web_projects\arbitrage_kw\script_instance.py", line 31, in run_script
    self.driver.get('https://leon.bet/ru/live/soccer')
  File "C:\web_projects\arbitrage_kw\venv\lib\site-packages\selenium\webdriver\remote\webdriver.py", line 441, in get
    self.execute(Command.GET, {'url': url})
  File "C:\web_projects\arbitrage_kw\venv\lib\site-packages\selenium\webdriver\remote\webdriver.py", line 429, in execute
    self.error_handler.check_response(response)
  File "C:\web_projects\arbitrage_kw\venv\lib\site-packages\selenium\webdriver\remote\errorhandler.py", line 243, in check_response
    raise exception_class(message, screen, stacktrace)
selenium.common.exceptions.WebDriverException: Message: unknown error: net::ERR_CONNECTION_RESET
  (Session info: headless chrome=107.0.5304.88)
Stacktrace:
Backtrace:
	Ordinal0 [0x007A1ED3+2236115]
	Ordinal0 [0x007392F1+1807089]
	Ordinal0 [0x006466FD+812797]
	Ordinal0 [0x00642C42+797762]
	Ordinal0 [0x00639C1D+760861]
	Ordinal0 [0x0063A9FC+764412]
	Ordinal0 [0x00639E5F+761439]
	Ordinal0 [0x00639350+758608]
	Ordinal0 [0x006392C1+758465]
	Ordinal0 [0x00638113+753939]
	Ordinal0 [0x0063861D+755229]
	Ordinal0 [0x0064800E+819214]
	Ordinal0 [0x006A60CD+1204429]
	Ordinal0 [0x00691A8C+1120908]
	Ordinal0 [0x006A59E2+1202658]
	Ordinal0 [0x006918A6+1120422]
	Ordinal0 [0x0066A73D+960317]
	Ordinal0 [0x0066B71F+964383]
	GetHandleVerifier [0x00A4E7E2+2743074]
	GetHandleVerifier [0x00A408D4+2685972]
	GetHandleVerifier [0x00832BAA+532202]
	GetHandleVerifier [0x00831990+527568]
	Ordinal0 [0x0074080C+1837068]
	Ordinal0 [0x00744CD8+1854680]
	Ordinal0 [0x00744DC5+1854917]
	Ordinal0 [0x0074ED64+1895780]
	BaseThreadInitThunk [0x75C1FA29+25]
	RtlGetAppContainerNamedObjectPath [0x77027BBE+286]
	RtlGetAppContainerNamedObjectPath [0x77027B8E+238]

2022-11-03 12:15:05,410 - my_application - ERROR - Message: unknown error: net::ERR_CONNECTION_RESET
  (Session info: headless chrome=107.0.5304.88)
Stacktrace:
Backtrace:
	Ordinal0 [0x007A1ED3+2236115]
	Ordinal0 [0x007392F1+1807089]
	Ordinal0 [0x006466FD+812797]
	Ordinal0 [0x00642C42+797762]
	Ordinal0 [0x00639C1D+760861]
	Ordinal0 [0x0063A9FC+764412]
	Ordinal0 [0x00639E5F+761439]
	Ordinal0 [0x00639350+758608]
	Ordinal0 [0x006392C1+758465]
	Ordinal0 [0x00638113+753939]
	Ordinal0 [0x0063861D+755229]
	Ordinal0 [0x0064800E+819214]
	Ordinal0 [0x006A60CD+1204429]
	Ordinal0 [0x00691A8C+1120908]
	Ordinal0 [0x006A59E2+1202658]
	Ordinal0 [0x006918A6+1120422]
	Ordinal0 [0x0066A73D+960317]
	Ordinal0 [0x0066B71F+964383]
	GetHandleVerifier [0x00A4E7E2+2743074]
	GetHandleVerifier [0x00A408D4+2685972]
	GetHandleVerifier [0x00832BAA+532202]
	GetHandleVerifier [0x00831990+527568]
	Ordinal0 [0x0074080C+1837068]
	Ordinal0 [0x00744CD8+1854680]
	Ordinal0 [0x00744DC5+1854917]
	Ordinal0 [0x0074ED64+1895780]
	BaseThreadInitThunk [0x75C1FA29+25]
	RtlGetAppContainerNamedObjectPath [0x77027BBE+286]
	RtlGetAppContainerNamedObjectPath [0x77027B8E+238]
Traceback (most recent call last):
  File "C:\web_projects\arbitrage_kw\main_widget.py", line 150, in run
    self.br.run_script()
  File "C:\web_projects\arbitrage_kw\script_instance.py", line 31, in run_script
    self.driver.get('https://leon.bet/ru/live/soccer')
  File "C:\web_projects\arbitrage_kw\venv\lib\site-packages\selenium\webdriver\remote\webdriver.py", line 441, in get
    self.execute(Command.GET, {'url': url})
  File "C:\web_projects\arbitrage_kw\venv\lib\site-packages\selenium\webdriver\remote\webdriver.py", line 429, in execute
    self.error_handler.check_response(response)
  File "C:\web_projects\arbitrage_kw\venv\lib\site-packages\selenium\webdriver\remote\errorhandler.py", line 243, in check_response
    raise exception_class(message, screen, stacktrace)
selenium.common.exceptions.WebDriverException: Message: unknown error: net::ERR_CONNECTION_RESET
  (Session info: headless chrome=107.0.5304.88)
Stacktrace:
Backtrace:
	Ordinal0 [0x007A1ED3+2236115]
	Ordinal0 [0x007392F1+1807089]
	Ordinal0 [0x006466FD+812797]
	Ordinal0 [0x00642C42+797762]
	Ordinal0 [0x00639C1D+760861]
	Ordinal0 [0x0063A9FC+764412]
	Ordinal0 [0x00639E5F+761439]
	Ordinal0 [0x00639350+758608]
	Ordinal0 [0x006392C1+758465]
	Ordinal0 [0x00638113+753939]
	Ordinal0 [0x0063861D+755229]
	Ordinal0 [0x0064800E+819214]
	Ordinal0 [0x006A60CD+1204429]
	Ordinal0 [0x00691A8C+1120908]
	Ordinal0 [0x006A59E2+1202658]
	Ordinal0 [0x006918A6+1120422]
	Ordinal0 [0x0066A73D+960317]
	Ordinal0 [0x0066B71F+964383]
	GetHandleVerifier [0x00A4E7E2+2743074]
	GetHandleVerifier [0x00A408D4+2685972]
	GetHandleVerifier [0x00832BAA+532202]
	GetHandleVerifier [0x00831990+527568]
	Ordinal0 [0x0074080C+1837068]
	Ordinal0 [0x00744CD8+1854680]
	Ordinal0 [0x00744DC5+1854917]
	Ordinal0 [0x0074ED64+1895780]
	BaseThreadInitThunk [0x75C1FA29+25]
	RtlGetAppContainerNamedObjectPath [0x77027BBE+286]
	RtlGetAppContainerNamedObjectPath [0x77027B8E+238]

2022-11-03 12:17:42,650 - my_application - ERROR - Message: unknown error: net::ERR_CONNECTION_RESET
  (Session info: headless chrome=107.0.5304.88)
Stacktrace:
Backtrace:
	Ordinal0 [0x007A1ED3+2236115]
	Ordinal0 [0x007392F1+1807089]
	Ordinal0 [0x006466FD+812797]
	Ordinal0 [0x00642C42+797762]
	Ordinal0 [0x00639C1D+760861]
	Ordinal0 [0x0063A9FC+764412]
	Ordinal0 [0x00639E5F+761439]
	Ordinal0 [0x00639350+758608]
	Ordinal0 [0x006392C1+758465]
	Ordinal0 [0x00638113+753939]
	Ordinal0 [0x0063861D+755229]
	Ordinal0 [0x0064800E+819214]
	Ordinal0 [0x006A60CD+1204429]
	Ordinal0 [0x00691A8C+1120908]
	Ordinal0 [0x006A59E2+1202658]
	Ordinal0 [0x006918A6+1120422]
	Ordinal0 [0x0066A73D+960317]
	Ordinal0 [0x0066B71F+964383]
	GetHandleVerifier [0x00A4E7E2+2743074]
	GetHandleVerifier [0x00A408D4+2685972]
	GetHandleVerifier [0x00832BAA+532202]
	GetHandleVerifier [0x00831990+527568]
	Ordinal0 [0x0074080C+1837068]
	Ordinal0 [0x00744CD8+1854680]
	Ordinal0 [0x00744DC5+1854917]
	Ordinal0 [0x0074ED64+1895780]
	BaseThreadInitThunk [0x75C1FA29+25]
	RtlGetAppContainerNamedObjectPath [0x77027BBE+286]
	RtlGetAppContainerNamedObjectPath [0x77027B8E+238]
Traceback (most recent call last):
  File "C:\web_projects\arbitrage_kw\main_widget.py", line 150, in run
    self.br.run_script()
  File "C:\web_projects\arbitrage_kw\script_instance.py", line 31, in run_script
    self.driver.get('https://leon.bet/ru/live/soccer')
  File "C:\web_projects\arbitrage_kw\venv\lib\site-packages\selenium\webdriver\remote\webdriver.py", line 441, in get
    self.execute(Command.GET, {'url': url})
  File "C:\web_projects\arbitrage_kw\venv\lib\site-packages\selenium\webdriver\remote\webdriver.py", line 429, in execute
    self.error_handler.check_response(response)
  File "C:\web_projects\arbitrage_kw\venv\lib\site-packages\selenium\webdriver\remote\errorhandler.py", line 243, in check_response
    raise exception_class(message, screen, stacktrace)
selenium.common.exceptions.WebDriverException: Message: unknown error: net::ERR_CONNECTION_RESET
  (Session info: headless chrome=107.0.5304.88)
Stacktrace:
Backtrace:
	Ordinal0 [0x007A1ED3+2236115]
	Ordinal0 [0x007392F1+1807089]
	Ordinal0 [0x006466FD+812797]
	Ordinal0 [0x00642C42+797762]
	Ordinal0 [0x00639C1D+760861]
	Ordinal0 [0x0063A9FC+764412]
	Ordinal0 [0x00639E5F+761439]
	Ordinal0 [0x00639350+758608]
	Ordinal0 [0x006392C1+758465]
	Ordinal0 [0x00638113+753939]
	Ordinal0 [0x0063861D+755229]
	Ordinal0 [0x0064800E+819214]
	Ordinal0 [0x006A60CD+1204429]
	Ordinal0 [0x00691A8C+1120908]
	Ordinal0 [0x006A59E2+1202658]
	Ordinal0 [0x006918A6+1120422]
	Ordinal0 [0x0066A73D+960317]
	Ordinal0 [0x0066B71F+964383]
	GetHandleVerifier [0x00A4E7E2+2743074]
	GetHandleVerifier [0x00A408D4+2685972]
	GetHandleVerifier [0x00832BAA+532202]
	GetHandleVerifier [0x00831990+527568]
	Ordinal0 [0x0074080C+1837068]
	Ordinal0 [0x00744CD8+1854680]
	Ordinal0 [0x00744DC5+1854917]
	Ordinal0 [0x0074ED64+1895780]
	BaseThreadInitThunk [0x75C1FA29+25]
	RtlGetAppContainerNamedObjectPath [0x77027BBE+286]
	RtlGetAppContainerNamedObjectPath [0x77027B8E+238]

